{
 "cells": [
  {
   "cell_type": "markdown",
   "metadata": {},
   "source": [
    "# Errors and Exceptions\n",
    "\n",
    "While executing a python program we may encounter errors. There are 2 types of errors:\n",
    "\n",
    "1. Syntax Errors - When you don't follow the proper structure of the python program (Like missing a quote during initialising a string).\n",
    "2. Exceptions - Sometimes even when the syntax is correct, errors may occur when the program is run or executed. These run time errors are called Exceptions (like trying to divide by zero or file does not exist).\n",
    "\n",
    "If Exceptions are not handled properly, the program will crash and come to a sudden & unexpected halt."
   ]
  },
  {
   "cell_type": "markdown",
   "metadata": {},
   "source": [
    "### Syntax Errors"
   ]
  },
  {
   "cell_type": "code",
   "execution_count": 1,
   "metadata": {},
   "outputs": [
    {
     "ename": "SyntaxError",
     "evalue": "EOL while scanning string literal (<ipython-input-1-683e48a9a7a9>, line 1)",
     "output_type": "error",
     "traceback": [
      "\u001b[0;36m  File \u001b[0;32m\"<ipython-input-1-683e48a9a7a9>\"\u001b[0;36m, line \u001b[0;32m1\u001b[0m\n\u001b[0;31m    print('Hello)\u001b[0m\n\u001b[0m                 ^\u001b[0m\n\u001b[0;31mSyntaxError\u001b[0m\u001b[0;31m:\u001b[0m EOL while scanning string literal\n"
     ]
    }
   ],
   "source": [
    "print('Hello)"
   ]
  },
  {
   "cell_type": "markdown",
   "metadata": {},
   "source": [
    "### Exceptions"
   ]
  },
  {
   "cell_type": "code",
   "execution_count": 2,
   "metadata": {},
   "outputs": [
    {
     "ename": "ZeroDivisionError",
     "evalue": "division by zero",
     "output_type": "error",
     "traceback": [
      "\u001b[0;31m---------------------------------------------------------------------------\u001b[0m",
      "\u001b[0;31mZeroDivisionError\u001b[0m                         Traceback (most recent call last)",
      "\u001b[0;32m<ipython-input-2-b710d87c980c>\u001b[0m in \u001b[0;36m<module>\u001b[0;34m()\u001b[0m\n\u001b[0;32m----> 1\u001b[0;31m \u001b[0;36m1\u001b[0m \u001b[0;34m/\u001b[0m \u001b[0;36m0\u001b[0m\u001b[0;34m\u001b[0m\u001b[0m\n\u001b[0m",
      "\u001b[0;31mZeroDivisionError\u001b[0m: division by zero"
     ]
    }
   ],
   "source": [
    "1 / 0"
   ]
  },
  {
   "cell_type": "code",
   "execution_count": 3,
   "metadata": {},
   "outputs": [
    {
     "ename": "FileNotFoundError",
     "evalue": "[Errno 2] No such file or directory: 'doesnotexistfile.txt'",
     "output_type": "error",
     "traceback": [
      "\u001b[0;31m---------------------------------------------------------------------------\u001b[0m",
      "\u001b[0;31mFileNotFoundError\u001b[0m                         Traceback (most recent call last)",
      "\u001b[0;32m<ipython-input-3-c5316aff5424>\u001b[0m in \u001b[0;36m<module>\u001b[0;34m()\u001b[0m\n\u001b[0;32m----> 1\u001b[0;31m \u001b[0mopen\u001b[0m\u001b[0;34m(\u001b[0m\u001b[0;34m'doesnotexistfile.txt'\u001b[0m\u001b[0;34m)\u001b[0m\u001b[0;34m\u001b[0m\u001b[0m\n\u001b[0m",
      "\u001b[0;31mFileNotFoundError\u001b[0m: [Errno 2] No such file or directory: 'doesnotexistfile.txt'"
     ]
    }
   ],
   "source": [
    "open('doesnotexistfile.txt')"
   ]
  },
  {
   "cell_type": "markdown",
   "metadata": {},
   "source": [
    "### Built-in Exceptions\n",
    "\n",
    "Python creates an Exception object whenever a runtime error occurs. There are a number of built-in exceptions."
   ]
  },
  {
   "cell_type": "code",
   "execution_count": 7,
   "metadata": {},
   "outputs": [
    {
     "name": "stdout",
     "output_type": "stream",
     "text": [
      "<module 'builtins' (built-in)>\n"
     ]
    }
   ],
   "source": [
    "print(locals()['__builtins__'])"
   ]
  },
  {
   "cell_type": "markdown",
   "metadata": {},
   "source": [
    "Following are some of the built-in exceptions.\n",
    "\n",
    "* ZeroDivisionError - Raised when you try to divide a number by zero\n",
    "* FileNotFoundError - Raised when a file required does not exist\n",
    "* SyntaxError - Raised when proper syntax is not applied\n",
    "* NameError - Raised when a variable is not found in local or global scope\n",
    "* KeyError - Raised when a key is not found in a dictionary"
   ]
  },
  {
   "cell_type": "markdown",
   "metadata": {},
   "source": [
    "### Handling Exceptions"
   ]
  },
  {
   "cell_type": "markdown",
   "metadata": {},
   "source": [
    "Python provides 'try/except' statements to handle the exceptions. The operation which can raise exception is placed inside the 'try' statement and code that handles exception is written in the 'except' clause."
   ]
  },
  {
   "cell_type": "code",
   "execution_count": 11,
   "metadata": {},
   "outputs": [
    {
     "name": "stdout",
     "output_type": "stream",
     "text": [
      "<class 'ZeroDivisionError'>\n"
     ]
    }
   ],
   "source": [
    "import sys\n",
    "def divide(a,b):\n",
    "    try:\n",
    "        return a / b\n",
    "    except: \n",
    "        print(sys.exc_info()[0])\n",
    "        \n",
    "divide (1,2)\n",
    "divide (2,0) # This will be captured by the 'except' clause"
   ]
  },
  {
   "cell_type": "code",
   "execution_count": 12,
   "metadata": {},
   "outputs": [
    {
     "name": "stdout",
     "output_type": "stream",
     "text": [
      "Error occured <class 'ZeroDivisionError'>\n"
     ]
    }
   ],
   "source": [
    "# print custom error message\n",
    "def divide(a,b):\n",
    "    try:\n",
    "        return a / b\n",
    "    except: \n",
    "        print('Error occured',sys.exc_info()[0])\n",
    "        \n",
    "divide (1,2)\n",
    "divide (2,0) # This will be captured by the 'except' clause"
   ]
  },
  {
   "cell_type": "markdown",
   "metadata": {},
   "source": [
    "#### Catching Specific Exceptions\n",
    "\n",
    "A try clause can have any number of except clause to capture specific exceptions and only one will be executed in case an exception occurs. We can use tuple of values to specify multiple exceptions in an exception clause"
   ]
  },
  {
   "cell_type": "code",
   "execution_count": 18,
   "metadata": {},
   "outputs": [
    {
     "name": "stdout",
     "output_type": "stream",
     "text": [
      "Number cannot be divided by zero or non-integer\n",
      "Error Occured <class 'TypeError'>\n"
     ]
    }
   ],
   "source": [
    "def divide(a,b):\n",
    "    try:\n",
    "        return a / b\n",
    "    except (ZeroDivisionError): \n",
    "        print('Number cannot be divided by zero or non-integer')\n",
    "    except:\n",
    "        print('Error Occured',sys.exc_info()[0])\n",
    "        \n",
    "divide (1,2)\n",
    "divide (2,0) # This will be captured by the 'except - zero division error' clause\n",
    "divide (2,'a') # This will be captured by the generic 'except' clause"
   ]
  },
  {
   "cell_type": "code",
   "execution_count": 19,
   "metadata": {},
   "outputs": [
    {
     "name": "stdout",
     "output_type": "stream",
     "text": [
      "Number cannot be divided by zero or non-integer\n",
      "Number cannot be divided by zero or non-integer\n"
     ]
    }
   ],
   "source": [
    "def divide(a,b):\n",
    "    try:\n",
    "        return a / b\n",
    "    except (ZeroDivisionError, TypeError): # use a tuple to capture multiple errors\n",
    "        print('Number cannot be divided by zero or non-integer')\n",
    "    except:\n",
    "        print('Error Occured',sys.exc_info()[0])\n",
    "        \n",
    "divide (1,2)\n",
    "divide (2,0) # This will be captured by the 'except - zero division error' clause\n",
    "divide (2,'a') # This will be captured by the generic 'except' clause"
   ]
  },
  {
   "cell_type": "markdown",
   "metadata": {},
   "source": [
    "The last except clause may omit the exception name(s), to serve as a wildcard. Use this with extreme caution, since it is easy to mask a real programming error in this way! It can also be used to print an error message and then re-raise the exception (allowing a caller to handle the exception as well):"
   ]
  },
  {
   "cell_type": "code",
   "execution_count": 20,
   "metadata": {},
   "outputs": [
    {
     "name": "stdout",
     "output_type": "stream",
     "text": [
      "OS error: [Errno 2] No such file or directory: 'myfile.txt'\n"
     ]
    }
   ],
   "source": [
    "import sys\n",
    "\n",
    "try:\n",
    "    f = open('myfile.txt')\n",
    "    s = f.readline()\n",
    "    i = int(s.strip())\n",
    "except OSError as err:\n",
    "    print(\"OS error: {0}\".format(err))\n",
    "except ValueError:\n",
    "    print(\"Could not convert data to an integer.\")\n",
    "except:\n",
    "    print(\"Unexpected error:\", sys.exc_info()[0])\n",
    "    raise"
   ]
  },
  {
   "cell_type": "markdown",
   "metadata": {},
   "source": [
    "The try … except statement has an optional else clause, which, when present, must follow all except clauses. It is useful for code that must be executed if the try clause does not raise an exception. For example:"
   ]
  },
  {
   "cell_type": "code",
   "execution_count": 21,
   "metadata": {},
   "outputs": [
    {
     "name": "stdout",
     "output_type": "stream",
     "text": [
      "cannot open -f\n",
      "/Users/cnc/Library/Jupyter/runtime/kernel-7c3ac5b3-b13f-4801-bd7c-2495eafdfe0b.json has 12 lines\n"
     ]
    }
   ],
   "source": [
    "for arg in sys.argv[1:]:\n",
    "    try:\n",
    "        f = open(arg, 'r')\n",
    "    except OSError:\n",
    "        print('cannot open', arg)\n",
    "    else:\n",
    "        print(arg, 'has', len(f.readlines()), 'lines')\n",
    "        f.close()"
   ]
  },
  {
   "cell_type": "markdown",
   "metadata": {},
   "source": [
    "The use of the else clause is better than adding additional code to the try clause because it avoids accidentally catching an exception that wasn’t raised by the code being protected by the try … except statement."
   ]
  },
  {
   "cell_type": "markdown",
   "metadata": {},
   "source": [
    "#### Exception Instances\n",
    "\n",
    "The except clause may specify a variable after the exception name. The variable is bound to an exception instance with the arguments stored in instance.args. For convenience, the exception instance defines __str__() so the arguments can be printed directly without having to reference .args. "
   ]
  },
  {
   "cell_type": "code",
   "execution_count": 40,
   "metadata": {},
   "outputs": [
    {
     "name": "stdout",
     "output_type": "stream",
     "text": [
      "<class 'Exception'>\n",
      "('1002', 'Custom Exception Occured')\n",
      "('1002', 'Custom Exception Occured')\n",
      "Error Number: 1002\n",
      "Error Description: Custom Exception Occured\n"
     ]
    }
   ],
   "source": [
    "try:\n",
    "    raise Exception('1002','Custom Exception Occured')\n",
    "except Exception as inst:\n",
    "    print(type(inst))\n",
    "    print(inst)\n",
    "    print(inst.args)\n",
    "    errno, errdesc = inst.args\n",
    "    print('Error Number:',errno)\n",
    "    print('Error Description:',errdesc)"
   ]
  },
  {
   "cell_type": "markdown",
   "metadata": {},
   "source": [
    "Exception handlers don’t just handle exceptions if they occur immediately in the try clause, but also if they occur inside functions that are called (even indirectly) in the try clause. For example:"
   ]
  },
  {
   "cell_type": "code",
   "execution_count": 38,
   "metadata": {},
   "outputs": [
    {
     "name": "stdout",
     "output_type": "stream",
     "text": [
      "Handling Error -  division by zero\n"
     ]
    }
   ],
   "source": [
    "def func_will_fail():\n",
    "    return 1 / 0\n",
    "\n",
    "try:\n",
    "    func_will_fail()\n",
    "except ZeroDivisionError as err:\n",
    "    print('Handling Error - ',err)"
   ]
  },
  {
   "cell_type": "markdown",
   "metadata": {},
   "source": [
    "### Raise Exceptions\n",
    "\n",
    "The **raise** statement allows the programmer to force a specified exception to occur. For example:"
   ]
  },
  {
   "cell_type": "code",
   "execution_count": 35,
   "metadata": {},
   "outputs": [
    {
     "ename": "NameError",
     "evalue": "Error Occured",
     "output_type": "error",
     "traceback": [
      "\u001b[0;31m---------------------------------------------------------------------------\u001b[0m",
      "\u001b[0;31mNameError\u001b[0m                                 Traceback (most recent call last)",
      "\u001b[0;32m<ipython-input-35-d3d2da6432b8>\u001b[0m in \u001b[0;36m<module>\u001b[0;34m()\u001b[0m\n\u001b[0;32m----> 1\u001b[0;31m \u001b[0;32mraise\u001b[0m \u001b[0mNameError\u001b[0m\u001b[0;34m(\u001b[0m\u001b[0;34m'Error Occured'\u001b[0m\u001b[0;34m)\u001b[0m\u001b[0;34m\u001b[0m\u001b[0m\n\u001b[0m",
      "\u001b[0;31mNameError\u001b[0m: Error Occured"
     ]
    }
   ],
   "source": [
    "raise NameError('Error Occured')"
   ]
  },
  {
   "cell_type": "markdown",
   "metadata": {},
   "source": [
    "If you need to determine whether an exception was raised but don’t intend to handle it, a simpler form of the raise statement allows you to re-raise the exception:"
   ]
  },
  {
   "cell_type": "code",
   "execution_count": 36,
   "metadata": {},
   "outputs": [
    {
     "name": "stdout",
     "output_type": "stream",
     "text": [
      "Captured Exception\n"
     ]
    },
    {
     "ename": "NameError",
     "evalue": "Error Captured",
     "output_type": "error",
     "traceback": [
      "\u001b[0;31m---------------------------------------------------------------------------\u001b[0m",
      "\u001b[0;31mNameError\u001b[0m                                 Traceback (most recent call last)",
      "\u001b[0;32m<ipython-input-36-7df1e345bdc8>\u001b[0m in \u001b[0;36m<module>\u001b[0;34m()\u001b[0m\n\u001b[1;32m      1\u001b[0m \u001b[0;32mtry\u001b[0m\u001b[0;34m:\u001b[0m\u001b[0;34m\u001b[0m\u001b[0m\n\u001b[0;32m----> 2\u001b[0;31m     \u001b[0;32mraise\u001b[0m \u001b[0mNameError\u001b[0m\u001b[0;34m(\u001b[0m\u001b[0;34m'Error Captured'\u001b[0m\u001b[0;34m)\u001b[0m\u001b[0;34m\u001b[0m\u001b[0m\n\u001b[0m\u001b[1;32m      3\u001b[0m \u001b[0;32mexcept\u001b[0m \u001b[0mNameError\u001b[0m\u001b[0;34m:\u001b[0m\u001b[0;34m\u001b[0m\u001b[0m\n\u001b[1;32m      4\u001b[0m     \u001b[0mprint\u001b[0m\u001b[0;34m(\u001b[0m\u001b[0;34m'Captured Exception'\u001b[0m\u001b[0;34m)\u001b[0m\u001b[0;34m\u001b[0m\u001b[0m\n\u001b[1;32m      5\u001b[0m     \u001b[0;32mraise\u001b[0m\u001b[0;34m\u001b[0m\u001b[0m\n",
      "\u001b[0;31mNameError\u001b[0m: Error Captured"
     ]
    }
   ],
   "source": [
    "try:\n",
    "    raise NameError('Error Captured')\n",
    "except NameError:\n",
    "    print('Captured Exception')\n",
    "    raise\n",
    "    "
   ]
  },
  {
   "cell_type": "markdown",
   "metadata": {},
   "source": [
    "### User Exceptions\n",
    "\n",
    "Python has many built-in exceptions which forces your program to output an error when something in it goes wrong.\n",
    "\n",
    "However, sometimes you may need to create custom exceptions that serves your purpose.\n",
    "\n",
    "In Python, users can define such exceptions by creating a new class. This exception class has to be derived, either directly or indirectly, from Exception class. Most of the built-in exceptions are also derived form this class."
   ]
  },
  {
   "cell_type": "code",
   "execution_count": 30,
   "metadata": {
    "collapsed": true
   },
   "outputs": [],
   "source": [
    "class CustomError(Exception):\n",
    "    pass"
   ]
  },
  {
   "cell_type": "code",
   "execution_count": 31,
   "metadata": {},
   "outputs": [
    {
     "ename": "CustomError",
     "evalue": "",
     "output_type": "error",
     "traceback": [
      "\u001b[0;31m---------------------------------------------------------------------------\u001b[0m",
      "\u001b[0;31mCustomError\u001b[0m                               Traceback (most recent call last)",
      "\u001b[0;32m<ipython-input-31-59d3a407da42>\u001b[0m in \u001b[0;36m<module>\u001b[0;34m()\u001b[0m\n\u001b[0;32m----> 1\u001b[0;31m \u001b[0;32mraise\u001b[0m \u001b[0mCustomError\u001b[0m\u001b[0;34m(\u001b[0m\u001b[0;34m)\u001b[0m\u001b[0;34m\u001b[0m\u001b[0m\n\u001b[0m",
      "\u001b[0;31mCustomError\u001b[0m: "
     ]
    }
   ],
   "source": [
    "raise CustomError()"
   ]
  },
  {
   "cell_type": "code",
   "execution_count": 32,
   "metadata": {},
   "outputs": [
    {
     "ename": "CustomError",
     "evalue": "Unexpected Error Occured",
     "output_type": "error",
     "traceback": [
      "\u001b[0;31m---------------------------------------------------------------------------\u001b[0m",
      "\u001b[0;31mCustomError\u001b[0m                               Traceback (most recent call last)",
      "\u001b[0;32m<ipython-input-32-1b2beb538761>\u001b[0m in \u001b[0;36m<module>\u001b[0;34m()\u001b[0m\n\u001b[0;32m----> 1\u001b[0;31m \u001b[0;32mraise\u001b[0m \u001b[0mCustomError\u001b[0m\u001b[0;34m(\u001b[0m\u001b[0;34m'Unexpected Error Occured'\u001b[0m\u001b[0;34m)\u001b[0m\u001b[0;34m\u001b[0m\u001b[0m\n\u001b[0m",
      "\u001b[0;31mCustomError\u001b[0m: Unexpected Error Occured"
     ]
    }
   ],
   "source": [
    "raise CustomError('Unexpected Error Occured')"
   ]
  },
  {
   "cell_type": "markdown",
   "metadata": {},
   "source": [
    "Here, we have created a user-defined exception called CustomError which is derived from the Exception class. This new exception can be raised, like other exceptions, using the raise statement with an optional error message.\n",
    "\n"
   ]
  },
  {
   "cell_type": "markdown",
   "metadata": {},
   "source": [
    "#### Point to Note\n",
    "\n",
    "When we are developing a large Python program, it is a good practice to place all the user-defined exceptions that our program raises in a separate file. Many standard modules do this. They define their exceptions separately as exceptions.py or errors.py (generally but not always).\n",
    "\n",
    "Most exceptions are defined with names that end in “Error,” similar to the naming of the standard exceptions."
   ]
  },
  {
   "cell_type": "code",
   "execution_count": 33,
   "metadata": {},
   "outputs": [
    {
     "name": "stdout",
     "output_type": "stream",
     "text": [
      "Enter a number: 5\n",
      "This value is too small, try again!\n",
      "\n",
      "Enter a number: 10\n",
      "Congratulations! You guessed it correctly.\n"
     ]
    }
   ],
   "source": [
    "# define Python user-defined exceptions\n",
    "class Error(Exception):\n",
    "   \"\"\"Base class for other exceptions\"\"\"\n",
    "   pass\n",
    "\n",
    "class ValueTooSmallError(Error):\n",
    "   \"\"\"Raised when the input value is too small\"\"\"\n",
    "   pass\n",
    "\n",
    "class ValueTooLargeError(Error):\n",
    "   \"\"\"Raised when the input value is too large\"\"\"\n",
    "   pass\n",
    "\n",
    "# our main program\n",
    "# user guesses a number until he/she gets it right\n",
    "\n",
    "# you need to guess this number\n",
    "number = 10\n",
    "\n",
    "while True:\n",
    "   try:\n",
    "       i_num = int(input(\"Enter a number: \"))\n",
    "       if i_num < number:\n",
    "           raise ValueTooSmallError\n",
    "       elif i_num > number:\n",
    "           raise ValueTooLargeError\n",
    "       break\n",
    "   except ValueTooSmallError:\n",
    "       print(\"This value is too small, try again!\")\n",
    "       print()\n",
    "   except ValueTooLargeError:\n",
    "       print(\"This value is too large, try again!\")\n",
    "       print()\n",
    "\n",
    "print(\"Congratulations! You guessed it correctly.\")"
   ]
  },
  {
   "cell_type": "markdown",
   "metadata": {},
   "source": [
    "Here, we have defined a base class called Error.\n",
    "\n",
    "The other two exceptions (ValueTooSmallError and ValueTooLargeError) that are actually raised by our program are derived from this class. This is the standard way to define user-defined exceptions in Python programming."
   ]
  },
  {
   "cell_type": "markdown",
   "metadata": {},
   "source": [
    "Many standard modules define their own exceptions to report errors that may occur in functions they define. A detailed example is given below:"
   ]
  },
  {
   "cell_type": "code",
   "execution_count": 34,
   "metadata": {
    "collapsed": true
   },
   "outputs": [],
   "source": [
    "class Error(Exception):\n",
    "    \"\"\"Base class for exceptions in this module.\"\"\"\n",
    "    pass\n",
    "\n",
    "class InputError(Error):\n",
    "    \"\"\"Exception raised for errors in the input.\n",
    "\n",
    "    Attributes:\n",
    "        expression -- input expression in which the error occurred\n",
    "        message -- explanation of the error\n",
    "    \"\"\"\n",
    "\n",
    "    def __init__(self, expression, message):\n",
    "        self.expression = expression\n",
    "        self.message = message\n",
    "\n",
    "class TransitionError(Error):\n",
    "    \"\"\"Raised when an operation attempts a state transition that's not\n",
    "    allowed.\n",
    "\n",
    "    Attributes:\n",
    "        previous -- state at beginning of transition\n",
    "        next -- attempted new state\n",
    "        message -- explanation of why the specific transition is not allowed\n",
    "    \"\"\"\n",
    "\n",
    "    def __init__(self, previous, next, message):\n",
    "        self.previous = previous\n",
    "        self.next = next\n",
    "        self.message = message"
   ]
  },
  {
   "cell_type": "markdown",
   "metadata": {},
   "source": [
    "### Clean up Actions"
   ]
  },
  {
   "cell_type": "markdown",
   "metadata": {},
   "source": [
    "The **try** statement in Python can have an optional **finally** clause. This clause is executed no matter what, and is generally used to release external resources.\n",
    "\n",
    "A finally clause is always executed before leaving the try statement, whether an exception has occurred or not. When an exception has occurred in the try clause and has not been handled by an except clause (or it has occurred in an except or else clause), it is re-raised after the finally clause has been executed. \n",
    "\n",
    "The finally clause is also executed “on the way out” when any other clause of the try statement is left via a break, continue or return statement."
   ]
  },
  {
   "cell_type": "code",
   "execution_count": 24,
   "metadata": {},
   "outputs": [
    {
     "name": "stdout",
     "output_type": "stream",
     "text": [
      "Bye\n"
     ]
    },
    {
     "ename": "NameError",
     "evalue": "name 'KeyBoardInterrupt' is not defined",
     "output_type": "error",
     "traceback": [
      "\u001b[0;31m---------------------------------------------------------------------------\u001b[0m",
      "\u001b[0;31mNameError\u001b[0m                                 Traceback (most recent call last)",
      "\u001b[0;32m<ipython-input-24-9d554bc1c68d>\u001b[0m in \u001b[0;36m<module>\u001b[0;34m()\u001b[0m\n\u001b[1;32m      1\u001b[0m \u001b[0;32mtry\u001b[0m\u001b[0;34m:\u001b[0m\u001b[0;34m\u001b[0m\u001b[0m\n\u001b[0;32m----> 2\u001b[0;31m     \u001b[0;32mraise\u001b[0m \u001b[0mKeyBoardInterrupt\u001b[0m\u001b[0;34m\u001b[0m\u001b[0m\n\u001b[0m\u001b[1;32m      3\u001b[0m \u001b[0;32mfinally\u001b[0m\u001b[0;34m:\u001b[0m\u001b[0;34m\u001b[0m\u001b[0m\n\u001b[1;32m      4\u001b[0m     \u001b[0mprint\u001b[0m\u001b[0;34m(\u001b[0m\u001b[0;34m'Bye'\u001b[0m\u001b[0;34m)\u001b[0m\u001b[0;34m\u001b[0m\u001b[0m\n",
      "\u001b[0;31mNameError\u001b[0m: name 'KeyBoardInterrupt' is not defined"
     ]
    }
   ],
   "source": [
    "try:\n",
    "    raise KeyBoardInterrupt\n",
    "finally:\n",
    "    print('Bye')"
   ]
  },
  {
   "cell_type": "code",
   "execution_count": 26,
   "metadata": {
    "collapsed": true
   },
   "outputs": [],
   "source": [
    "def divide(a,b):\n",
    "    try:\n",
    "        result = a / b\n",
    "    except ZeroDivisionError:\n",
    "        print('Number cannot be divided by zero')\n",
    "    else:\n",
    "        print('Result',result)\n",
    "    finally:\n",
    "        print('Executed Finally Clause')\n",
    "        "
   ]
  },
  {
   "cell_type": "code",
   "execution_count": 27,
   "metadata": {},
   "outputs": [
    {
     "name": "stdout",
     "output_type": "stream",
     "text": [
      "Result 2.0\n",
      "Executed Finally Clause\n"
     ]
    }
   ],
   "source": [
    "divide(2,1)"
   ]
  },
  {
   "cell_type": "code",
   "execution_count": 28,
   "metadata": {},
   "outputs": [
    {
     "name": "stdout",
     "output_type": "stream",
     "text": [
      "Number cannot be divided by zero\n",
      "Executed Finally Clause\n"
     ]
    }
   ],
   "source": [
    "divide(2,0)"
   ]
  },
  {
   "cell_type": "code",
   "execution_count": 29,
   "metadata": {},
   "outputs": [
    {
     "name": "stdout",
     "output_type": "stream",
     "text": [
      "Executed Finally Clause\n"
     ]
    },
    {
     "ename": "TypeError",
     "evalue": "unsupported operand type(s) for /: 'str' and 'str'",
     "output_type": "error",
     "traceback": [
      "\u001b[0;31m---------------------------------------------------------------------------\u001b[0m",
      "\u001b[0;31mTypeError\u001b[0m                                 Traceback (most recent call last)",
      "\u001b[0;32m<ipython-input-29-fc217289e134>\u001b[0m in \u001b[0;36m<module>\u001b[0;34m()\u001b[0m\n\u001b[0;32m----> 1\u001b[0;31m \u001b[0mdivide\u001b[0m\u001b[0;34m(\u001b[0m\u001b[0;34m'1'\u001b[0m\u001b[0;34m,\u001b[0m\u001b[0;34m'2'\u001b[0m\u001b[0;34m)\u001b[0m\u001b[0;34m\u001b[0m\u001b[0m\n\u001b[0m",
      "\u001b[0;32m<ipython-input-26-c2a4f470101a>\u001b[0m in \u001b[0;36mdivide\u001b[0;34m(a, b)\u001b[0m\n\u001b[1;32m      1\u001b[0m \u001b[0;32mdef\u001b[0m \u001b[0mdivide\u001b[0m\u001b[0;34m(\u001b[0m\u001b[0ma\u001b[0m\u001b[0;34m,\u001b[0m\u001b[0mb\u001b[0m\u001b[0;34m)\u001b[0m\u001b[0;34m:\u001b[0m\u001b[0;34m\u001b[0m\u001b[0m\n\u001b[1;32m      2\u001b[0m     \u001b[0;32mtry\u001b[0m\u001b[0;34m:\u001b[0m\u001b[0;34m\u001b[0m\u001b[0m\n\u001b[0;32m----> 3\u001b[0;31m         \u001b[0mresult\u001b[0m \u001b[0;34m=\u001b[0m \u001b[0ma\u001b[0m \u001b[0;34m/\u001b[0m \u001b[0mb\u001b[0m\u001b[0;34m\u001b[0m\u001b[0m\n\u001b[0m\u001b[1;32m      4\u001b[0m     \u001b[0;32mexcept\u001b[0m \u001b[0mZeroDivisionError\u001b[0m\u001b[0;34m:\u001b[0m\u001b[0;34m\u001b[0m\u001b[0m\n\u001b[1;32m      5\u001b[0m         \u001b[0mprint\u001b[0m\u001b[0;34m(\u001b[0m\u001b[0;34m'Number cannot be divided by zero'\u001b[0m\u001b[0;34m)\u001b[0m\u001b[0;34m\u001b[0m\u001b[0m\n",
      "\u001b[0;31mTypeError\u001b[0m: unsupported operand type(s) for /: 'str' and 'str'"
     ]
    }
   ],
   "source": [
    "divide('1','2')"
   ]
  },
  {
   "cell_type": "markdown",
   "metadata": {},
   "source": [
    "Please note that the **TypeError** raised by dividing two strings is not handled by the except clause and therefore re-raised after the finally clause has been executed."
   ]
  },
  {
   "cell_type": "markdown",
   "metadata": {},
   "source": [
    "### Pre Clean up Actions\n",
    "\n",
    "Some objects define standard clean-up actions to be undertaken when the object is no longer needed.\n",
    "\n",
    "Look at the following example, which tries to open a file and print its contents to the screen."
   ]
  },
  {
   "cell_type": "code",
   "execution_count": null,
   "metadata": {
    "collapsed": true
   },
   "outputs": [],
   "source": [
    "for line in open(\"myfile.txt\"):\n",
    "    print(line, end=\"\")"
   ]
  },
  {
   "cell_type": "markdown",
   "metadata": {},
   "source": [
    "The problem with this code is that it leaves the file open for an indeterminate amount of time after this part of the code has finished executing. This is not a best practice."
   ]
  },
  {
   "cell_type": "code",
   "execution_count": 23,
   "metadata": {},
   "outputs": [
    {
     "name": "stdout",
     "output_type": "stream",
     "text": [
      "This is a test file"
     ]
    }
   ],
   "source": [
    "with open(\"test.txt\") as f:\n",
    "    for line in f:\n",
    "        print(line, end=\"\")"
   ]
  },
  {
   "cell_type": "markdown",
   "metadata": {},
   "source": [
    "The **with** statement allows objects like files to be used in a way that ensures they are always cleaned up promptly and correctly.\n",
    "\n",
    "After the statement is executed, the file f is always closed, even if a problem was encountered while processing the lines."
   ]
  },
  {
   "cell_type": "markdown",
   "metadata": {},
   "source": [
    "### References\n",
    "\n",
    "[Python Errors and Exception Handling - Official Documentation](https://docs.python.org/3/tutorial/errors.html)\n",
    "\n",
    "[Python Exception Handling - By Programiz.com](https://www.programiz.com/python-programming/exception-handling)"
   ]
  }
 ],
 "metadata": {
  "kernelspec": {
   "display_name": "Python 3",
   "language": "python",
   "name": "python3"
  },
  "language_info": {
   "codemirror_mode": {
    "name": "ipython",
    "version": 3
   },
   "file_extension": ".py",
   "mimetype": "text/x-python",
   "name": "python",
   "nbconvert_exporter": "python",
   "pygments_lexer": "ipython3",
   "version": "3.6.1"
  }
 },
 "nbformat": 4,
 "nbformat_minor": 2
}
